[2025-09-06T12:12:50.555-0300] {local_task_job_runner.py:120} INFO - ::group::Pre task execution logs
[2025-09-06T12:12:50.737-0300] {taskinstance.py:2076} INFO - Dependencies all met for dep_context=non-requeueable deps ti=<TaskInstance: ETL_FLIGHTS.extract manual__2025-09-06T15:12:36.020647+00:00 [queued]>
[2025-09-06T12:12:50.792-0300] {taskinstance.py:2076} INFO - Dependencies all met for dep_context=requeueable deps ti=<TaskInstance: ETL_FLIGHTS.extract manual__2025-09-06T15:12:36.020647+00:00 [queued]>
[2025-09-06T12:12:50.794-0300] {taskinstance.py:2306} INFO - Starting attempt 1 of 2
[2025-09-06T12:12:51.633-0300] {taskinstance.py:2330} INFO - Executing <Task(PythonOperator): extract> on 2025-09-06 15:12:36.020647+00:00
[2025-09-06T12:12:51.653-0300] {standard_task_runner.py:63} INFO - Started process 10872 to run task
[2025-09-06T12:12:51.670-0300] {standard_task_runner.py:90} INFO - Running: ['airflow', 'tasks', 'run', 'ETL_FLIGHTS', 'extract', 'manual__2025-09-06T15:12:36.020647+00:00', '--job-id', '36', '--raw', '--subdir', 'DAGS_FOLDER/ETL_FLIGHTS.py', '--cfg-path', '/tmp/tmpqbun_cmy']
[2025-09-06T12:12:51.674-0300] {standard_task_runner.py:91} INFO - Job 36: Subtask extract
[2025-09-06T12:12:52.305-0300] {task_command.py:426} INFO - Running <TaskInstance: ETL_FLIGHTS.extract manual__2025-09-06T15:12:36.020647+00:00 [running]> on host sebastian-Aspire-A515-54
[2025-09-06T12:12:53.119-0300] {taskinstance.py:2648} INFO - Exporting env vars: AIRFLOW_CTX_DAG_OWNER='airflow' AIRFLOW_CTX_DAG_ID='ETL_FLIGHTS' AIRFLOW_CTX_TASK_ID='extract' AIRFLOW_CTX_EXECUTION_DATE='2025-09-06T15:12:36.020647+00:00' AIRFLOW_CTX_TRY_NUMBER='1' AIRFLOW_CTX_DAG_RUN_ID='manual__2025-09-06T15:12:36.020647+00:00'
[2025-09-06T12:12:53.123-0300] {taskinstance.py:430} INFO - ::endgroup::
[2025-09-06T12:12:53.125-0300] {taskinstance.py:441} INFO - ::group::Post task execution logs
[2025-09-06T12:12:53.126-0300] {taskinstance.py:2905} ERROR - Task failed with exception
Traceback (most recent call last):
  File "/home/sebastian/Documentos/Seba/Challenges/Fligoo/.venv/lib/python3.10/site-packages/airflow/models/taskinstance.py", line 465, in _execute_task
    result = _execute_callable(context=context, **execute_callable_kwargs)
  File "/home/sebastian/Documentos/Seba/Challenges/Fligoo/.venv/lib/python3.10/site-packages/airflow/models/taskinstance.py", line 432, in _execute_callable
    return execute_callable(context=context, **execute_callable_kwargs)
  File "/home/sebastian/Documentos/Seba/Challenges/Fligoo/.venv/lib/python3.10/site-packages/airflow/models/baseoperator.py", line 401, in wrapper
    return func(self, *args, **kwargs)
  File "/home/sebastian/Documentos/Seba/Challenges/Fligoo/.venv/lib/python3.10/site-packages/airflow/operators/python.py", line 235, in execute
    return_value = self.execute_callable()
  File "/home/sebastian/Documentos/Seba/Challenges/Fligoo/.venv/lib/python3.10/site-packages/airflow/operators/python.py", line 252, in execute_callable
    return self.python_callable(*self.op_args, **self.op_kwargs)
  File "/home/sebastian/Documentos/Seba/Challenges/Fligoo/airflow_local/dags/ETL_FLIGHTS.py", line 79, in extract
    raise ValueError("Falta AVIATIONSTACK_KEY en el entorno.")
ValueError: Falta AVIATIONSTACK_KEY en el entorno.
[2025-09-06T12:12:53.196-0300] {taskinstance.py:1206} INFO - Marking task as UP_FOR_RETRY. dag_id=ETL_FLIGHTS, task_id=extract, run_id=manual__2025-09-06T15:12:36.020647+00:00, execution_date=20250906T151236, start_date=20250906T151250, end_date=20250906T151253
[2025-09-06T12:12:53.588-0300] {standard_task_runner.py:110} ERROR - Failed to execute job 36 for task extract (Falta AVIATIONSTACK_KEY en el entorno.; 10872)
[2025-09-06T12:12:53.650-0300] {local_task_job_runner.py:240} INFO - Task exited with return code 1
[2025-09-06T12:12:53.731-0300] {taskinstance.py:3503} INFO - 0 downstream tasks scheduled from follow-on schedule check
[2025-09-06T12:12:53.733-0300] {local_task_job_runner.py:222} INFO - ::endgroup::
