[2025-09-05T22:31:12.543-0300] {local_task_job_runner.py:120} INFO - ::group::Pre task execution logs
[2025-09-05T22:31:12.577-0300] {taskinstance.py:2076} INFO - Dependencies all met for dep_context=non-requeueable deps ti=<TaskInstance: ETL_FLIGHTS.load manual__2025-09-06T01:27:32.997530+00:00 [queued]>
[2025-09-05T22:31:12.592-0300] {taskinstance.py:2076} INFO - Dependencies all met for dep_context=requeueable deps ti=<TaskInstance: ETL_FLIGHTS.load manual__2025-09-06T01:27:32.997530+00:00 [queued]>
[2025-09-05T22:31:12.592-0300] {taskinstance.py:2306} INFO - Starting attempt 2 of 2
[2025-09-05T22:31:12.937-0300] {taskinstance.py:2330} INFO - Executing <Task(PythonOperator): load> on 2025-09-06 01:27:32.997530+00:00
[2025-09-05T22:31:12.954-0300] {standard_task_runner.py:63} INFO - Started process 42627 to run task
[2025-09-05T22:31:12.963-0300] {standard_task_runner.py:90} INFO - Running: ['airflow', 'tasks', 'run', 'ETL_FLIGHTS', 'load', 'manual__2025-09-06T01:27:32.997530+00:00', '--job-id', '5', '--raw', '--subdir', 'DAGS_FOLDER/ETL_FLIGHTS.py', '--cfg-path', '/tmp/tmpkzu599u5']
[2025-09-05T22:31:12.969-0300] {standard_task_runner.py:91} INFO - Job 5: Subtask load
[2025-09-05T22:31:13.348-0300] {task_command.py:426} INFO - Running <TaskInstance: ETL_FLIGHTS.load manual__2025-09-06T01:27:32.997530+00:00 [running]> on host sebastian-Aspire-A515-54
[2025-09-05T22:31:13.813-0300] {taskinstance.py:2648} INFO - Exporting env vars: AIRFLOW_CTX_DAG_OWNER='airflow' AIRFLOW_CTX_DAG_ID='ETL_FLIGHTS' AIRFLOW_CTX_TASK_ID='load' AIRFLOW_CTX_EXECUTION_DATE='2025-09-06T01:27:32.997530+00:00' AIRFLOW_CTX_TRY_NUMBER='2' AIRFLOW_CTX_DAG_RUN_ID='manual__2025-09-06T01:27:32.997530+00:00'
[2025-09-05T22:31:13.825-0300] {taskinstance.py:430} INFO - ::endgroup::
[2025-09-05T22:31:13.905-0300] {logging_mixin.py:188} WARNING - /home/sebastian/Documentos/Seba/Challenges/Fligoo/airflow/dags/ETL_FLIGHTS.py:102 UserWarning: pandas only supports SQLAlchemy connectable (engine/connection) or database string URI or sqlite3 DBAPI2 connection. Other DBAPI2 objects are not tested. Please consider using SQLAlchemy.
[2025-09-05T22:31:13.906-0300] {taskinstance.py:441} INFO - ::group::Post task execution logs
[2025-09-05T22:31:13.907-0300] {taskinstance.py:2905} ERROR - Task failed with exception
Traceback (most recent call last):
  File "/home/sebastian/Documentos/Seba/Challenges/Fligoo/.venv-airflow/lib/python3.10/site-packages/airflow/models/taskinstance.py", line 465, in _execute_task
    result = _execute_callable(context=context, **execute_callable_kwargs)
  File "/home/sebastian/Documentos/Seba/Challenges/Fligoo/.venv-airflow/lib/python3.10/site-packages/airflow/models/taskinstance.py", line 432, in _execute_callable
    return execute_callable(context=context, **execute_callable_kwargs)
  File "/home/sebastian/Documentos/Seba/Challenges/Fligoo/.venv-airflow/lib/python3.10/site-packages/airflow/models/baseoperator.py", line 401, in wrapper
    return func(self, *args, **kwargs)
  File "/home/sebastian/Documentos/Seba/Challenges/Fligoo/.venv-airflow/lib/python3.10/site-packages/airflow/operators/python.py", line 235, in execute
    return_value = self.execute_callable()
  File "/home/sebastian/Documentos/Seba/Challenges/Fligoo/.venv-airflow/lib/python3.10/site-packages/airflow/operators/python.py", line 252, in execute_callable
    return self.python_callable(*self.op_args, **self.op_kwargs)
  File "/home/sebastian/Documentos/Seba/Challenges/Fligoo/airflow/dags/ETL_FLIGHTS.py", line 102, in load
    df.to_sql("testdata", engine, if_exists="append", index=False, method="multi", chunksize=500)
  File "/home/sebastian/Documentos/Seba/Challenges/Fligoo/.venv-airflow/lib/python3.10/site-packages/pandas/util/_decorators.py", line 333, in wrapper
    return func(*args, **kwargs)
  File "/home/sebastian/Documentos/Seba/Challenges/Fligoo/.venv-airflow/lib/python3.10/site-packages/pandas/core/generic.py", line 3106, in to_sql
    return sql.to_sql(
  File "/home/sebastian/Documentos/Seba/Challenges/Fligoo/.venv-airflow/lib/python3.10/site-packages/pandas/io/sql.py", line 844, in to_sql
    return pandas_sql.to_sql(
  File "/home/sebastian/Documentos/Seba/Challenges/Fligoo/.venv-airflow/lib/python3.10/site-packages/pandas/io/sql.py", line 2840, in to_sql
    table.create()
  File "/home/sebastian/Documentos/Seba/Challenges/Fligoo/.venv-airflow/lib/python3.10/site-packages/pandas/io/sql.py", line 986, in create
    if self.exists():
  File "/home/sebastian/Documentos/Seba/Challenges/Fligoo/.venv-airflow/lib/python3.10/site-packages/pandas/io/sql.py", line 972, in exists
    return self.pd_sql.has_table(self.name, self.schema)
  File "/home/sebastian/Documentos/Seba/Challenges/Fligoo/.venv-airflow/lib/python3.10/site-packages/pandas/io/sql.py", line 2855, in has_table
    return len(self.execute(query, [name]).fetchall()) > 0
  File "/home/sebastian/Documentos/Seba/Challenges/Fligoo/.venv-airflow/lib/python3.10/site-packages/pandas/io/sql.py", line 2662, in execute
    cur = self.con.cursor()
AttributeError: 'Engine' object has no attribute 'cursor'
[2025-09-05T22:31:13.914-0300] {taskinstance.py:1206} INFO - Marking task as FAILED. dag_id=ETL_FLIGHTS, task_id=load, run_id=manual__2025-09-06T01:27:32.997530+00:00, execution_date=20250906T012732, start_date=20250906T013112, end_date=20250906T013113
[2025-09-05T22:31:14.248-0300] {standard_task_runner.py:110} ERROR - Failed to execute job 5 for task load ('Engine' object has no attribute 'cursor'; 42627)
[2025-09-05T22:31:14.345-0300] {local_task_job_runner.py:240} INFO - Task exited with return code 1
[2025-09-05T22:31:14.371-0300] {taskinstance.py:3503} INFO - 0 downstream tasks scheduled from follow-on schedule check
[2025-09-05T22:31:14.372-0300] {local_task_job_runner.py:222} INFO - ::endgroup::
