[2025-09-06T10:35:36.114-0300] {local_task_job_runner.py:120} INFO - ::group::Pre task execution logs
[2025-09-06T10:35:36.175-0300] {taskinstance.py:2076} INFO - Dependencies all met for dep_context=non-requeueable deps ti=<TaskInstance: ETL_FLIGHTS.load manual__2025-09-06T13:29:17.049497+00:00 [queued]>
[2025-09-06T10:35:36.189-0300] {taskinstance.py:2076} INFO - Dependencies all met for dep_context=requeueable deps ti=<TaskInstance: ETL_FLIGHTS.load manual__2025-09-06T13:29:17.049497+00:00 [queued]>
[2025-09-06T10:35:36.189-0300] {taskinstance.py:2306} INFO - Starting attempt 2 of 3
[2025-09-06T10:35:36.492-0300] {taskinstance.py:2330} INFO - Executing <Task(PythonOperator): load> on 2025-09-06 13:29:17.049497+00:00
[2025-09-06T10:35:36.512-0300] {standard_task_runner.py:63} INFO - Started process 61268 to run task
[2025-09-06T10:35:36.531-0300] {standard_task_runner.py:90} INFO - Running: ['airflow', 'tasks', 'run', 'ETL_FLIGHTS', 'load', 'manual__2025-09-06T13:29:17.049497+00:00', '--job-id', '21', '--raw', '--subdir', 'DAGS_FOLDER/ETL_FLIGHTS.py', '--cfg-path', '/tmp/tmp8pwy67ao']
[2025-09-06T10:35:36.534-0300] {standard_task_runner.py:91} INFO - Job 21: Subtask load
[2025-09-06T10:35:36.860-0300] {task_command.py:426} INFO - Running <TaskInstance: ETL_FLIGHTS.load manual__2025-09-06T13:29:17.049497+00:00 [running]> on host sebastian-Aspire-A515-54
[2025-09-06T10:35:37.304-0300] {taskinstance.py:2648} INFO - Exporting env vars: AIRFLOW_CTX_DAG_OWNER='airflow' AIRFLOW_CTX_DAG_ID='ETL_FLIGHTS' AIRFLOW_CTX_TASK_ID='load' AIRFLOW_CTX_EXECUTION_DATE='2025-09-06T13:29:17.049497+00:00' AIRFLOW_CTX_TRY_NUMBER='2' AIRFLOW_CTX_DAG_RUN_ID='manual__2025-09-06T13:29:17.049497+00:00'
[2025-09-06T10:35:37.305-0300] {taskinstance.py:430} INFO - ::endgroup::
[2025-09-06T10:35:37.639-0300] {taskinstance.py:441} INFO - ::group::Post task execution logs
[2025-09-06T10:35:37.640-0300] {taskinstance.py:2905} ERROR - Task failed with exception
Traceback (most recent call last):
  File "/home/sebastian/Documentos/Seba/Challenges/Fligoo/.venv-airflow/lib/python3.10/site-packages/sqlalchemy/engine/base.py", line 1910, in _execute_context
    self.dialect.do_execute(
  File "/home/sebastian/Documentos/Seba/Challenges/Fligoo/.venv-airflow/lib/python3.10/site-packages/sqlalchemy/engine/default.py", line 736, in do_execute
    cursor.execute(statement, parameters)
psycopg2.errors.UniqueViolation: could not create unique index "ux_testdata_natural"
DETAIL:  Key (flight_date, flight_number, airline_name, departure_airport, arrival_airport)=(2025-09-06, 2171, Japan Airlines, Itami, Akita) is duplicated.


The above exception was the direct cause of the following exception:

Traceback (most recent call last):
  File "/home/sebastian/Documentos/Seba/Challenges/Fligoo/.venv-airflow/lib/python3.10/site-packages/airflow/models/taskinstance.py", line 465, in _execute_task
    result = _execute_callable(context=context, **execute_callable_kwargs)
  File "/home/sebastian/Documentos/Seba/Challenges/Fligoo/.venv-airflow/lib/python3.10/site-packages/airflow/models/taskinstance.py", line 432, in _execute_callable
    return execute_callable(context=context, **execute_callable_kwargs)
  File "/home/sebastian/Documentos/Seba/Challenges/Fligoo/.venv-airflow/lib/python3.10/site-packages/airflow/models/baseoperator.py", line 401, in wrapper
    return func(self, *args, **kwargs)
  File "/home/sebastian/Documentos/Seba/Challenges/Fligoo/.venv-airflow/lib/python3.10/site-packages/airflow/operators/python.py", line 235, in execute
    return_value = self.execute_callable()
  File "/home/sebastian/Documentos/Seba/Challenges/Fligoo/.venv-airflow/lib/python3.10/site-packages/airflow/operators/python.py", line 252, in execute_callable
    return self.python_callable(*self.op_args, **self.op_kwargs)
  File "/home/sebastian/Documentos/Seba/Challenges/Fligoo/airflow/dags/ETL_FLIGHTS.py", line 115, in load
    conn.execute(text(create_idx))
  File "/home/sebastian/Documentos/Seba/Challenges/Fligoo/.venv-airflow/lib/python3.10/site-packages/sqlalchemy/engine/base.py", line 1385, in execute
    return meth(self, multiparams, params, _EMPTY_EXECUTION_OPTS)
  File "/home/sebastian/Documentos/Seba/Challenges/Fligoo/.venv-airflow/lib/python3.10/site-packages/sqlalchemy/sql/elements.py", line 334, in _execute_on_connection
    return connection._execute_clauseelement(
  File "/home/sebastian/Documentos/Seba/Challenges/Fligoo/.venv-airflow/lib/python3.10/site-packages/sqlalchemy/engine/base.py", line 1577, in _execute_clauseelement
    ret = self._execute_context(
  File "/home/sebastian/Documentos/Seba/Challenges/Fligoo/.venv-airflow/lib/python3.10/site-packages/sqlalchemy/engine/base.py", line 1953, in _execute_context
    self._handle_dbapi_exception(
  File "/home/sebastian/Documentos/Seba/Challenges/Fligoo/.venv-airflow/lib/python3.10/site-packages/sqlalchemy/engine/base.py", line 2134, in _handle_dbapi_exception
    util.raise_(
  File "/home/sebastian/Documentos/Seba/Challenges/Fligoo/.venv-airflow/lib/python3.10/site-packages/sqlalchemy/util/compat.py", line 211, in raise_
    raise exception
  File "/home/sebastian/Documentos/Seba/Challenges/Fligoo/.venv-airflow/lib/python3.10/site-packages/sqlalchemy/engine/base.py", line 1910, in _execute_context
    self.dialect.do_execute(
  File "/home/sebastian/Documentos/Seba/Challenges/Fligoo/.venv-airflow/lib/python3.10/site-packages/sqlalchemy/engine/default.py", line 736, in do_execute
    cursor.execute(statement, parameters)
sqlalchemy.exc.IntegrityError: (psycopg2.errors.UniqueViolation) could not create unique index "ux_testdata_natural"
DETAIL:  Key (flight_date, flight_number, airline_name, departure_airport, arrival_airport)=(2025-09-06, 2171, Japan Airlines, Itami, Akita) is duplicated.

[SQL: 
    CREATE UNIQUE INDEX IF NOT EXISTS ux_testdata_natural
    ON testdata (flight_date, flight_number, airline_name, departure_airport, arrival_airport);
    ]
(Background on this error at: https://sqlalche.me/e/14/gkpj)
[2025-09-06T10:35:37.786-0300] {taskinstance.py:1206} INFO - Marking task as UP_FOR_RETRY. dag_id=ETL_FLIGHTS, task_id=load, run_id=manual__2025-09-06T13:29:17.049497+00:00, execution_date=20250906T132917, start_date=20250906T133536, end_date=20250906T133537
[2025-09-06T10:35:38.232-0300] {standard_task_runner.py:110} ERROR - Failed to execute job 21 for task load ((psycopg2.errors.UniqueViolation) could not create unique index "ux_testdata_natural"
DETAIL:  Key (flight_date, flight_number, airline_name, departure_airport, arrival_airport)=(2025-09-06, 2171, Japan Airlines, Itami, Akita) is duplicated.

[SQL: 
    CREATE UNIQUE INDEX IF NOT EXISTS ux_testdata_natural
    ON testdata (flight_date, flight_number, airline_name, departure_airport, arrival_airport);
    ]
(Background on this error at: https://sqlalche.me/e/14/gkpj); 61268)
[2025-09-06T10:35:38.278-0300] {local_task_job_runner.py:240} INFO - Task exited with return code 1
[2025-09-06T10:35:38.354-0300] {taskinstance.py:3503} INFO - 0 downstream tasks scheduled from follow-on schedule check
[2025-09-06T10:35:38.356-0300] {local_task_job_runner.py:222} INFO - ::endgroup::
