[2025-09-06T12:08:00.788-0300] {local_task_job_runner.py:120} INFO - ::group::Pre task execution logs
[2025-09-06T12:08:00.819-0300] {taskinstance.py:2076} INFO - Dependencies all met for dep_context=non-requeueable deps ti=<TaskInstance: ETL_FLIGHTS.transform manual__2025-09-06T15:06:02.684139+00:00 [queued]>
[2025-09-06T12:08:00.826-0300] {taskinstance.py:2076} INFO - Dependencies all met for dep_context=requeueable deps ti=<TaskInstance: ETL_FLIGHTS.transform manual__2025-09-06T15:06:02.684139+00:00 [queued]>
[2025-09-06T12:08:00.827-0300] {taskinstance.py:2306} INFO - Starting attempt 2 of 2
[2025-09-06T12:08:01.153-0300] {taskinstance.py:2330} INFO - Executing <Task(PythonOperator): transform> on 2025-09-06 15:06:02.684139+00:00
[2025-09-06T12:08:01.162-0300] {standard_task_runner.py:63} INFO - Started process 10249 to run task
[2025-09-06T12:08:01.168-0300] {standard_task_runner.py:90} INFO - Running: ['airflow', 'tasks', 'run', 'ETL_FLIGHTS', 'transform', 'manual__2025-09-06T15:06:02.684139+00:00', '--job-id', '35', '--raw', '--subdir', 'DAGS_FOLDER/ETL_FLIGHTS.py', '--cfg-path', '/tmp/tmpz1w72s36']
[2025-09-06T12:08:01.169-0300] {standard_task_runner.py:91} INFO - Job 35: Subtask transform
[2025-09-06T12:08:01.541-0300] {task_command.py:426} INFO - Running <TaskInstance: ETL_FLIGHTS.transform manual__2025-09-06T15:06:02.684139+00:00 [running]> on host sebastian-Aspire-A515-54
[2025-09-06T12:08:01.950-0300] {taskinstance.py:2648} INFO - Exporting env vars: AIRFLOW_CTX_DAG_OWNER='airflow' AIRFLOW_CTX_DAG_ID='ETL_FLIGHTS' AIRFLOW_CTX_TASK_ID='transform' AIRFLOW_CTX_EXECUTION_DATE='2025-09-06T15:06:02.684139+00:00' AIRFLOW_CTX_TRY_NUMBER='2' AIRFLOW_CTX_DAG_RUN_ID='manual__2025-09-06T15:06:02.684139+00:00'
[2025-09-06T12:08:01.951-0300] {taskinstance.py:430} INFO - ::endgroup::
[2025-09-06T12:08:01.961-0300] {taskinstance.py:441} INFO - ::group::Post task execution logs
[2025-09-06T12:08:01.962-0300] {taskinstance.py:2905} ERROR - Task failed with exception
Traceback (most recent call last):
  File "/home/sebastian/Documentos/Seba/Challenges/Fligoo/.venv/lib/python3.10/site-packages/airflow/models/taskinstance.py", line 465, in _execute_task
    result = _execute_callable(context=context, **execute_callable_kwargs)
  File "/home/sebastian/Documentos/Seba/Challenges/Fligoo/.venv/lib/python3.10/site-packages/airflow/models/taskinstance.py", line 432, in _execute_callable
    return execute_callable(context=context, **execute_callable_kwargs)
  File "/home/sebastian/Documentos/Seba/Challenges/Fligoo/.venv/lib/python3.10/site-packages/airflow/models/baseoperator.py", line 401, in wrapper
    return func(self, *args, **kwargs)
  File "/home/sebastian/Documentos/Seba/Challenges/Fligoo/.venv/lib/python3.10/site-packages/airflow/operators/python.py", line 235, in execute
    return_value = self.execute_callable()
  File "/home/sebastian/Documentos/Seba/Challenges/Fligoo/.venv/lib/python3.10/site-packages/airflow/operators/python.py", line 252, in execute_callable
    return self.python_callable(*self.op_args, **self.op_kwargs)
  File "/home/sebastian/Documentos/Seba/Challenges/Fligoo/airflow_local/dags/ETL_FLIGHTS.py", line 67, in transform
    df["flight_number"] = df["flight_number"].astype(str).str.strip()
  File "/home/sebastian/Documentos/Seba/Challenges/Fligoo/.venv/lib/python3.10/site-packages/pandas/core/frame.py", line 4107, in __getitem__
    indexer = self.columns.get_loc(key)
  File "/home/sebastian/Documentos/Seba/Challenges/Fligoo/.venv/lib/python3.10/site-packages/pandas/core/indexes/range.py", line 417, in get_loc
    raise KeyError(key)
KeyError: 'flight_number'
[2025-09-06T12:08:01.969-0300] {taskinstance.py:1206} INFO - Marking task as FAILED. dag_id=ETL_FLIGHTS, task_id=transform, run_id=manual__2025-09-06T15:06:02.684139+00:00, execution_date=20250906T150602, start_date=20250906T150800, end_date=20250906T150801
[2025-09-06T12:08:02.286-0300] {standard_task_runner.py:110} ERROR - Failed to execute job 35 for task transform ('flight_number'; 10249)
[2025-09-06T12:08:02.305-0300] {local_task_job_runner.py:240} INFO - Task exited with return code 1
[2025-09-06T12:08:02.330-0300] {taskinstance.py:3503} INFO - 0 downstream tasks scheduled from follow-on schedule check
[2025-09-06T12:08:03.047-0300] {local_task_job_runner.py:222} INFO - ::endgroup::
