[2025-09-06T13:11:47.272-0300] {local_task_job_runner.py:120} INFO - ::group::Pre task execution logs
[2025-09-06T13:11:47.435-0300] {taskinstance.py:2076} INFO - Dependencies all met for dep_context=non-requeueable deps ti=<TaskInstance: LOAD_FLIGHTS.extract manual__2025-09-06T16:11:21.379196+00:00 [queued]>
[2025-09-06T13:11:47.456-0300] {taskinstance.py:2076} INFO - Dependencies all met for dep_context=requeueable deps ti=<TaskInstance: LOAD_FLIGHTS.extract manual__2025-09-06T16:11:21.379196+00:00 [queued]>
[2025-09-06T13:11:47.457-0300] {taskinstance.py:2306} INFO - Starting attempt 1 of 2
[2025-09-06T13:11:47.822-0300] {taskinstance.py:2330} INFO - Executing <Task(PythonOperator): extract> on 2025-09-06 16:11:21.379196+00:00
[2025-09-06T13:11:47.839-0300] {standard_task_runner.py:63} INFO - Started process 18031 to run task
[2025-09-06T13:11:47.848-0300] {standard_task_runner.py:90} INFO - Running: ['airflow', 'tasks', 'run', 'LOAD_FLIGHTS', 'extract', 'manual__2025-09-06T16:11:21.379196+00:00', '--job-id', '48', '--raw', '--subdir', 'DAGS_FOLDER/LOAD_FLIGHTS.py', '--cfg-path', '/tmp/tmpi2w_ltbj']
[2025-09-06T13:11:47.851-0300] {standard_task_runner.py:91} INFO - Job 48: Subtask extract
[2025-09-06T13:11:48.578-0300] {task_command.py:426} INFO - Running <TaskInstance: LOAD_FLIGHTS.extract manual__2025-09-06T16:11:21.379196+00:00 [running]> on host sebastian-Aspire-A515-54
[2025-09-06T13:11:50.103-0300] {taskinstance.py:2648} INFO - Exporting env vars: AIRFLOW_CTX_DAG_OWNER='airflow' AIRFLOW_CTX_DAG_ID='LOAD_FLIGHTS' AIRFLOW_CTX_TASK_ID='extract' AIRFLOW_CTX_EXECUTION_DATE='2025-09-06T16:11:21.379196+00:00' AIRFLOW_CTX_TRY_NUMBER='1' AIRFLOW_CTX_DAG_RUN_ID='manual__2025-09-06T16:11:21.379196+00:00'
[2025-09-06T13:11:50.106-0300] {taskinstance.py:430} INFO - ::endgroup::
[2025-09-06T13:11:50.108-0300] {taskinstance.py:441} INFO - ::group::Post task execution logs
[2025-09-06T13:11:50.108-0300] {taskinstance.py:2905} ERROR - Task failed with exception
Traceback (most recent call last):
  File "/home/sebastian/Documentos/Seba/Challenges/Fligoo/.venv-airflow/lib/python3.10/site-packages/airflow/models/taskinstance.py", line 465, in _execute_task
    result = _execute_callable(context=context, **execute_callable_kwargs)
  File "/home/sebastian/Documentos/Seba/Challenges/Fligoo/.venv-airflow/lib/python3.10/site-packages/airflow/models/taskinstance.py", line 432, in _execute_callable
    return execute_callable(context=context, **execute_callable_kwargs)
  File "/home/sebastian/Documentos/Seba/Challenges/Fligoo/.venv-airflow/lib/python3.10/site-packages/airflow/models/baseoperator.py", line 401, in wrapper
    return func(self, *args, **kwargs)
  File "/home/sebastian/Documentos/Seba/Challenges/Fligoo/.venv-airflow/lib/python3.10/site-packages/airflow/operators/python.py", line 235, in execute
    return_value = self.execute_callable()
  File "/home/sebastian/Documentos/Seba/Challenges/Fligoo/.venv-airflow/lib/python3.10/site-packages/airflow/operators/python.py", line 252, in execute_callable
    return self.python_callable(*self.op_args, **self.op_kwargs)
  File "/home/sebastian/Documentos/Seba/Challenges/Fligoo/airflow_local/dags/LOAD_FLIGHTS.py", line 36, in _extract
    return job_extract(limit=100, status="active")
  File "/home/sebastian/Documentos/Seba/Challenges/Fligoo/airflow_local/jobs/extract.py", line 15, in extract
    raise ValueError("Falta AVIATIONSTACK_KEY (o API_KEY) en el entorno.")
ValueError: Falta AVIATIONSTACK_KEY (o API_KEY) en el entorno.
[2025-09-06T13:11:50.263-0300] {taskinstance.py:1206} INFO - Marking task as UP_FOR_RETRY. dag_id=LOAD_FLIGHTS, task_id=extract, run_id=manual__2025-09-06T16:11:21.379196+00:00, execution_date=20250906T161121, start_date=20250906T161147, end_date=20250906T161150
[2025-09-06T13:11:50.904-0300] {standard_task_runner.py:110} ERROR - Failed to execute job 48 for task extract (Falta AVIATIONSTACK_KEY (o API_KEY) en el entorno.; 18031)
[2025-09-06T13:11:50.957-0300] {local_task_job_runner.py:240} INFO - Task exited with return code 1
[2025-09-06T13:11:51.011-0300] {taskinstance.py:3503} INFO - 0 downstream tasks scheduled from follow-on schedule check
[2025-09-06T13:11:51.012-0300] {local_task_job_runner.py:222} INFO - ::endgroup::
