[2025-09-06T13:23:23.662-0300] {local_task_job_runner.py:120} INFO - ::group::Pre task execution logs
[2025-09-06T13:23:23.853-0300] {taskinstance.py:2076} INFO - Dependencies all met for dep_context=non-requeueable deps ti=<TaskInstance: LOAD_FLIGHTS.extract manual__2025-09-06T16:23:05.097761+00:00 [queued]>
[2025-09-06T13:23:23.869-0300] {taskinstance.py:2076} INFO - Dependencies all met for dep_context=requeueable deps ti=<TaskInstance: LOAD_FLIGHTS.extract manual__2025-09-06T16:23:05.097761+00:00 [queued]>
[2025-09-06T13:23:23.869-0300] {taskinstance.py:2306} INFO - Starting attempt 1 of 2
[2025-09-06T13:23:24.207-0300] {taskinstance.py:2330} INFO - Executing <Task(PythonOperator): extract> on 2025-09-06 16:23:05.097761+00:00
[2025-09-06T13:23:24.224-0300] {standard_task_runner.py:63} INFO - Started process 19204 to run task
[2025-09-06T13:23:24.237-0300] {standard_task_runner.py:90} INFO - Running: ['airflow', 'tasks', 'run', 'LOAD_FLIGHTS', 'extract', 'manual__2025-09-06T16:23:05.097761+00:00', '--job-id', '49', '--raw', '--subdir', 'DAGS_FOLDER/LOAD_FLIGHTS.py', '--cfg-path', '/tmp/tmpk3dr_c0c']
[2025-09-06T13:23:24.240-0300] {standard_task_runner.py:91} INFO - Job 49: Subtask extract
[2025-09-06T13:23:24.634-0300] {task_command.py:426} INFO - Running <TaskInstance: LOAD_FLIGHTS.extract manual__2025-09-06T16:23:05.097761+00:00 [running]> on host sebastian-Aspire-A515-54
[2025-09-06T13:23:26.718-0300] {taskinstance.py:2648} INFO - Exporting env vars: AIRFLOW_CTX_DAG_OWNER='airflow' AIRFLOW_CTX_DAG_ID='LOAD_FLIGHTS' AIRFLOW_CTX_TASK_ID='extract' AIRFLOW_CTX_EXECUTION_DATE='2025-09-06T16:23:05.097761+00:00' AIRFLOW_CTX_TRY_NUMBER='1' AIRFLOW_CTX_DAG_RUN_ID='manual__2025-09-06T16:23:05.097761+00:00'
[2025-09-06T13:23:26.721-0300] {taskinstance.py:430} INFO - ::endgroup::
[2025-09-06T13:23:26.723-0300] {taskinstance.py:441} INFO - ::group::Post task execution logs
[2025-09-06T13:23:26.724-0300] {taskinstance.py:2905} ERROR - Task failed with exception
Traceback (most recent call last):
  File "/home/sebastian/Documentos/Seba/Challenges/Fligoo/.venv-airflow/lib/python3.10/site-packages/airflow/models/taskinstance.py", line 465, in _execute_task
    result = _execute_callable(context=context, **execute_callable_kwargs)
  File "/home/sebastian/Documentos/Seba/Challenges/Fligoo/.venv-airflow/lib/python3.10/site-packages/airflow/models/taskinstance.py", line 432, in _execute_callable
    return execute_callable(context=context, **execute_callable_kwargs)
  File "/home/sebastian/Documentos/Seba/Challenges/Fligoo/.venv-airflow/lib/python3.10/site-packages/airflow/models/baseoperator.py", line 401, in wrapper
    return func(self, *args, **kwargs)
  File "/home/sebastian/Documentos/Seba/Challenges/Fligoo/.venv-airflow/lib/python3.10/site-packages/airflow/operators/python.py", line 235, in execute
    return_value = self.execute_callable()
  File "/home/sebastian/Documentos/Seba/Challenges/Fligoo/.venv-airflow/lib/python3.10/site-packages/airflow/operators/python.py", line 252, in execute_callable
    return self.python_callable(*self.op_args, **self.op_kwargs)
  File "/home/sebastian/Documentos/Seba/Challenges/Fligoo/airflow_local/jobs/extract.py", line 15, in extract
    raise ValueError("Falta AVIATIONSTACK_KEY (o API_KEY) en el entorno.")
ValueError: Falta AVIATIONSTACK_KEY (o API_KEY) en el entorno.
[2025-09-06T13:23:26.765-0300] {taskinstance.py:1206} INFO - Marking task as UP_FOR_RETRY. dag_id=LOAD_FLIGHTS, task_id=extract, run_id=manual__2025-09-06T16:23:05.097761+00:00, execution_date=20250906T162305, start_date=20250906T162323, end_date=20250906T162326
[2025-09-06T13:23:27.112-0300] {standard_task_runner.py:110} ERROR - Failed to execute job 49 for task extract (Falta AVIATIONSTACK_KEY (o API_KEY) en el entorno.; 19204)
[2025-09-06T13:23:27.151-0300] {local_task_job_runner.py:240} INFO - Task exited with return code 1
[2025-09-06T13:23:27.227-0300] {taskinstance.py:3503} INFO - 0 downstream tasks scheduled from follow-on schedule check
[2025-09-06T13:23:27.229-0300] {local_task_job_runner.py:222} INFO - ::endgroup::
